Running evaluation for gpt-4o-mini_openai...
Traceback (most recent call last):
  File "/Users/vinicius/code/estudo/teste/teste2.py", line 141, in <module>
    data = pd.read_csv(input_csv_path)
  File "/Users/vinicius/code/estudo/teste/.venvTeste/lib/python3.13/site-packages/pandas/io/parsers/readers.py", line 1026, in read_csv
    return _read(filepath_or_buffer, kwds)
  File "/Users/vinicius/code/estudo/teste/.venvTeste/lib/python3.13/site-packages/pandas/io/parsers/readers.py", line 620, in _read
    parser = TextFileReader(filepath_or_buffer, **kwds)
  File "/Users/vinicius/code/estudo/teste/.venvTeste/lib/python3.13/site-packages/pandas/io/parsers/readers.py", line 1620, in __init__
    self._engine = self._make_engine(f, self.engine)
                   ~~~~~~~~~~~~~~~~~^^^^^^^^^^^^^^^^
  File "/Users/vinicius/code/estudo/teste/.venvTeste/lib/python3.13/site-packages/pandas/io/parsers/readers.py", line 1880, in _make_engine
    self.handles = get_handle(
                   ~~~~~~~~~~^
        f,
        ^^
    ...<6 lines>...
        storage_options=self.options.get("storage_options", None),
        ^^^^^^^^^^^^^^^^^^^^^^^^^^^^^^^^^^^^^^^^^^^^^^^^^^^^^^^^^^
    )
    ^
  File "/Users/vinicius/code/estudo/teste/.venvTeste/lib/python3.13/site-packages/pandas/io/common.py", line 873, in get_handle
    handle = open(
        handle,
    ...<3 lines>...
        newline="",
    )
FileNotFoundError: [Errno 2] No such file or directory: './results_gpt-4o-mini_openai.csv'
